Workbook

Sheet Analysis
A1: 10 mM DOPC + 1 mM 2-nitrobenzaldehyde
A3: Full-record results | B3: DOPC 1 | C3: DOPC 2 | D3: DOPC 3
A4: Number of readings | B4: =COUNT(D347:D588) -> 242 | C4: =COUNT(D589:D831) -> 243 | D4: =COUNT(D832:D1074) -> 243
A5: Duration (min) | B5: =MAX(C347:C588) -> 20.070567 | C5: =MAX(C589:C831) -> 20.15365 | D5: =MAX(C832:C1074) -> 20.15365
A6: Initial pH | B6: =D347 -> 7.40645 | C6: =D589 -> 7.26225 | D6: =D832 -> 7.12843
A7: Final pH | B7: =D588 -> 3.89028 | C7: =D831 -> 3.45538 | D7: =D1074 -> 3.8003
A8: pH decrease at 12 min | B8: =B102-B246 -> 3.2011255 | C8: =C102-C246 -> 3.6161651 | D8: =D102-D246 -> 3.0751958
A9: Fitted pH infinity | B9: 3.6342208 | C9: 3.4511314 | D9: 3.7462072
A10: Fitted amplitude A | B10: 4.0951627 | C10: 4.2850071 | D10: 3.7139573
A11: Apparent k (min^-1) | B11: 0.15476512 | C11: 0.26892429 | D11: 0.21371341
A12: Half-response LN(2)/k (min) | B12: =LN(2)/B11 -> 4.478704 | C12: =LN(2)/C11 -> 2.5774807 | D12: =LN(2)/D11 -> 3.243349
A13: Exponential R^2 | B13: =1-B15/DEVSQ(D347:D588) -> 0.99261826 | C13: =1-C15/DEVSQ(D589:D831) -> 0.98813393 | D13: =1-D15/DEVSQ(D832:D1074) -> 0.98930093
A14: RMSE (pH) | B14: =SQRT(B15/B4) -> 0.091369849 | C14: =SQRT(C15/C4) -> 0.11475173 | D14: =SQRT(D15/D4) -> 0.098221574
A15: SSE = SUM(residual^2) | B15: =SUM(J347:J588) -> 2.0203247 | C15: =SUM(J589:J831) -> 3.1998144 | D15: =SUM(J832:J1074) -> 2.3443371
A16: Linear slope (pH/min) | B16: =SLOPE(D347:D588,C347:C588) -> -0.16848988 | C16: =SLOPE(D589:D831,C589:C831) -> -0.14930985 | D16: =SLOPE(D832:D1074,C832:C1074) -> -0.14187914
A17: Linear intercept | B17: =INTERCEPT(D347:D588,C347:C588) -> 6.5880645 | C17: =INTERCEPT(D589:D831,C589:C831) -> 5.7484817 | D17: =INTERCEPT(D832:D1074,C832:C1074) -> 6.0308442
A18: Linear R^2 | B18: =RSQ(D347:D588,C347:C588) -> 0.84961826 | C18: =RSQ(D589:D831,C589:C831) -> 0.68560208 | D18: =RSQ(D832:D1074,C832:C1074) -> 0.76186039
A19: First 100-s slope (pH/min) | B19: =SLOPE(D347:D367,C347:C367) -> -0.40510275 | C19: =SLOPE(D589:D609,C589:C609) -> -0.56104101 | D19: =SLOPE(D832:D852,C832:C852) -> -0.42608119
A20: Last 2-min slope (pH/min) | B20: =SLOPE(D564:D588,C564:C588) -> -0.026094255 | C20: =SLOPE(D807:D831,C807:C831) -> -0.018699945 | D20: =SLOPE(D1050:D1074,C1050:C1074) -> -0.027684399
A21: Time to pH 6 (min) | B21: =IF(D347<=6,0,IF(COUNT(P347:P588)=0,"Not reached",MIN(P347:P588))) -> 4.0481875 | C21: =IF(D589<=6,0,IF(COUNT(P589:P831)=0,"Not reached",MIN(P589:P831))) -> 2.3936974 | D21: =IF(D832<=6,0,IF(COUNT(P832:P1074)=0,"Not reached",MIN(P832:P1074))) -> 2.8556879
A22: Time to pH 5 (min) | B22: =IF(D347<=5,0,IF(COUNT(Q347:Q588)=0,"Not reached",MIN(Q347:Q588))) -> 6.8836954 | C22: =IF(D589<=5,0,IF(COUNT(Q589:Q831)=0,"Not reached",MIN(Q589:Q831))) -> 3.8031815 | D22: =IF(D832<=5,0,IF(COUNT(Q832:Q1074)=0,"Not reached",MIN(Q832:Q1074))) -> 4.9040886
A23: Time to pH 4 (min) | B23: =IF(D347<=4,0,IF(COUNT(R347:R588)=0,"Not reached",MIN(R347:R588))) -> 16.35534 | C23: =IF(D589<=4,0,IF(COUNT(R589:R831)=0,"Not reached",MIN(R589:R831))) -> 6.8491082 | D23: =IF(D832<=4,0,IF(COUNT(R832:R1074)=0,"Not reached",MIN(R832:R1074))) -> 13.071852
A24: Time to pH 3 (min) | B24: =IF(D347<=3,0,IF(COUNT(S347:S588)=0,"Not reached",MIN(S347:S588))) -> Not reached | C24: =IF(D589<=3,0,IF(COUNT(S589:S831)=0,"Not reached",MIN(S589:S831))) -> Not reached | D24: =IF(D832<=3,0,IF(COUNT(S832:S1074)=0,"Not reached",MIN(S832:S1074))) -> Not reached
A25: pH decrease at 20 min | B25: =B102-B342 -> 3.5122578 | C25: =C102-C342 -> 3.813 | D25: =D102-D342 -> 3.3326533
A27: pH(t) = pH infinity + A*EXP(-k*t). k describes the pH response.
A28: Fitted parameters are fixed results; other calculations use formulas.
A30: DOPC summary | B30: Mean | C30: Sample SD | D30: n
A31: Apparent k (min^-1) | B31: =AVERAGE(B11:D11) -> 0.21246761 | C31: =_xlfn.STDEV.S(B11:D11) -> 0.05708978 | D31: =COUNT(B11:D11) -> 3
C32: =C31/B31 -> 0.26869874
A35: Final pH | B35: =AVERAGE(B7:D7) -> 3.71532 | C35: =_xlfn.STDEV.S(B7:D7) -> 0.22956634 | D35: =COUNT(B7:D7) -> 3
A53: Series | B53: Full-record k (min^-1) | D53: Series
A54: DOPC 1 | B54: =B11 -> 0.15476512 | D54: DOPC 1
A55: DOPC 2 | B55: =C11 -> 0.26892429 | D55: DOPC 2
A56: DOPC 3 | B56: =D11 -> 0.21371341 | D56: DOPC 3
A100: Plot data (5-second interpolation)
A101: Time (min) | B101: DOPC 1 | C101: DOPC 2 | D101: DOPC 3 | E101: Reference A-B | F101: Reference D-E | G101: DOPC 1 fit | H101: DOPC 2 fit | I101: DOPC 3 fit | J101: Mean DOPC pH | K101: SD DOPC pH
A102: 0 | B102: =D347 -> 7.40645 | C102: =D589 -> 7.26225 | D102: =D832 -> 7.12843 | E102: =D1075 -> 3.9 | F102: =D1088 -> 6.73 | G102: =$B$9+$B$10*EXP(-$B$11*A102) -> 7.7293835 | H102: =$C$9+$C$10*EXP(-$C$11*A102) -> 7.7361385 | I102: =$D$9+$D$10*EXP(-$D$11*A102) -> 7.4601645 | J102: =AVERAGE(B102:D102) -> 7.26571 | K102: =_xlfn.STDEV.S(B102:D102) -> 0.13904229
A103: 0.083333333 | B103: =D347+($A103-C347)*(D348-D347)/(C348-C347) -> 7.42491 | C103: =D590+($A103-C590)*(D591-D590)/(C591-C590) -> 7.2771429 | D103: =D833+($A103-C833)*(D834-D833)/(C834-C833) -> 7.1329392 | E103: =D1075+($A103-C1075)*(D1076-D1075)/(C1076-C1075) -> 3.8775 | F103: =D1088+($A103-C1088)*(D1089-D1088)/(C1089-C1088) -> 6.6866667 | G103: =$B$9+$B$10*EXP(-$B$11*A103) -> 7.6769069 | H103: =$C$9+$C$10*EXP(-$C$11*A103) -> 7.641178 | I103: =$D$9+$D$10*EXP(-$D$11*A103) -> 7.3946065 | J103: =AVERAGE(B103:D103) -> 7.2783307 | K103: =_xlfn.STDEV.S(B103:D103) -> 0.145989
A104: 0.16666667 | B104: =D349+($A104-C349)*(D350-D349)/(C350-C349) -> 7.4087195 | C104: =D591+($A104-C591)*(D592-D591)/(C592-C591) -> 7.2436386 | D104: =D834+($A104-C834)*(D835-D834)/(C835-C834) -> 7.0983108 | E104: =D1075+($A104-C1075)*(D1076-D1075)/(C1076-C1075) -> 3.855 | F104: =D1088+($A104-C1088)*(D1089-D1088)/(C1089-C1088) -> 6.6433333 | G104: =$B$9+$B$10*EXP(-$B$11*A104) -> 7.6251028 | H104: =$C$9+$C$10*EXP(-$C$11*A104) -> 7.5483219 | I104: =$D$9+$D$10*EXP(-$D$11*A104) -> 7.3302057 | J104: =AVERAGE(B104:D104) -> 7.250223 | K104: =_xlfn.STDEV.S(B104:D104) -> 0.15530908
A105: 0.25 | B105: =D349+($A105-C349)*(D350-D349)/(C350-C349) -> 7.39607 | C105: =D592+($A105-C592)*(D593-D592)/(C593-C592) -> 7.1963571 | D105: =D835+($A105-C835)*(D836-D835)/(C836-C835) -> 7.057905 | E105: =D1075+($A105-C1075)*(D1076-D1075)/(C1076-C1075) -> 3.8325 | F105: =D1088+($A105-C1088)*(D1089-D1088)/(C1089-C1088) -> 6.6 | G105: =$B$9+$B$10*EXP(-$B$11*A105) -> 7.5739625 | H105: =$C$9+$C$10*EXP(-$C$11*A105) -> 7.4575236 | I105: =$D$9+$D$10*EXP(-$D$11*A105) -> 7.2669417 | J105: =AVERAGE(B105:D105) -> 7.2167774 | K105: =_xlfn.STDEV.S(B105:D105) -> 0.17000482
...

Sheet Raw Data
A1: Series | B1: computer_timestamp_utc | C1: elapsed_seconds | D1: elapsed_minutes | E1: sample_number | F1: arduino_millis | G1: raw_adc | H1: raw_sd | I1: voltage | J1: ph | K1: delta_ph | L1: ph_change_from_previous | M1: ph_rate_from_previous_per_min | O1: pH of 2- nitrobenzaldehyde curve in water and ethanol(1).xlsx
A2: DOPC 1 | B2: 46311.612 | C2: 0.281 | D2: 0.0046833333 | E2: 1 | F2: 704538 | G2: 313 | H2: 0.566 | I2: 1.529814 | J2: 7.40645 | K2: 0 | L2: 0 | O2: Reference A-B | R2: Reference D-E
A3: DOPC 1 | B3: 46311.612 | C3: 5.281 | D3: 0.088016667 | E3: 2 | F3: 709537 | G3: 312.36 | H3: 0.4921 | I3: 1.526686 | J3: 7.42491 | K3: 0.01846 | L3: 0.01846 | M3: 0.22152 | O3: Time (min) | P3: pH | R3: Time (min) | S3: pH
A4: DOPC 1 | B4: 46311.612 | C4: 10.265 | D4: 0.17108333 | E4: 3 | F4: 714536 | G4: 312.92 | H4: 0.552 | I4: 1.529423 | J4: 7.40876 | K4: 0.00231 | L4: -0.01615 | M4: -0.19442215 | O4: 0 | P4: 3.9 | R4: 0 | S4: 6.73
A5: DOPC 1 | B5: 46311.612 | C5: 15.281 | D5: 0.25468333 | E5: 4 | F5: 719537 | G5: 313.36 | H5: 0.4921 | I5: 1.531574 | J5: 7.39607 | K5: -0.01038 | L5: -0.01269 | M5: -0.15179426 | O5: 1 | P5: 3.63 | R5: 1 | S5: 6.21
A6: DOPC 1 | B6: 46311.612 | C6: 20.265 | D6: 0.33775 | E6: 5 | F6: 724537 | G6: 314.04 | H6: 0.1768 | I6: 1.534897 | J6: 7.37646 | K6: -0.02999 | L6: -0.01961 | M6: -0.23607544 | O6: 2 | P6: 3.54 | R6: 2 | S6: 5.49
A7: DOPC 1 | B7: 46311.612 | C7: 25.265 | D7: 0.42108333 | E7: 6 | F7: 729537 | G7: 315.28 | H7: 0.4507 | I7: 1.540958 | J7: 7.34069 | K7: -0.06576 | L7: -0.03577 | M7: -0.42924 | O7: 3 | P7: 3.42 | R7: 3 | S7: 4.28
A8: DOPC 1 | B8: 46311.613 | C8: 30.265 | D8: 0.50441667 | E8: 7 | F8: 734537 | G8: 316.12 | H8: 0.5154 | I8: 1.545063 | J8: 7.31647 | K8: -0.08998 | L8: -0.02422 | M8: -0.29064 | O8: 4 | P8: 3.36 | R8: 4 | S8: 3.89
A9: DOPC 1 | B9: 46311.613 | C9: 35.265 | D9: 0.58775 | E9: 8 | F9: 739537 | G9: 316.92 | H9: 0.476 | I9: 1.548974 | J9: 7.2934 | K9: -0.11305 | L9: -0.02307 | M9: -0.27684 | O9: 5 | P9: 3.32 | R9: 5 | S9: 3.73
A10: DOPC 1 | B10: 46311.613 | C10: 40.25 | D10: 0.67083333 | E10: 9 | F10: 744537 | G10: 318.32 | H10: 0.4677 | I10: 1.555816 | J10: 7.25302 | K10: -0.15343 | L10: -0.04038 | M10: -0.48601805 | O10: 6 | P10: 3.27 | R10: 6 | S10: 3.61
A11: DOPC 1 | B11: 46311.613 | C11: 45.265 | D11: 0.75441667 | E11: 10 | F11: 749537 | G11: 319.64 | H11: 0.4677 | I11: 1.562268 | J11: 7.21495 | K11: -0.1915 | L11: -0.03807 | M11: -0.45547358 | O11: 7 | P11: 3.24 | R11: 7 | S11: 3.52
A12: DOPC 1 | B12: 46311.613 | C12: 50.25 | D12: 0.8375 | E12: 11 | F12: 754537 | G12: 320.72 | H12: 0.5303 | I12: 1.567546 | J12: 7.18381 | K12: -0.22264 | L12: -0.03114 | M12: -0.37480441 | O12: 8 | P12: 3.21 | R12: 8 | S12: 3.48
A13: DOPC 1 | B13: 46311.613 | C13: 55.25 | D13: 0.92083333 | E13: 12 | F13: 759537 | G13: 322.28 | H13: 0.4507 | I13: 1.575171 | J13: 7.13881 | K13: -0.26764 | L13: -0.045 | M13: -0.54 | O13: 9 | P13: 3.19 | R13: 9 | S13: 3.36
A14: DOPC 1 | B14: 46311.613 | C14: 60.25 | D14: 1.0041667 | E14: 13 | F14: 764537 | G14: 323.84 | H14: 0.3644 | I14: 1.582796 | J14: 7.09382 | K14: -0.31263 | L14: -0.04499 | M14: -0.53988 | O14: 10 | P14: 3.17 | R14: 10 | S14: 3.31
A15: DOPC 1 | B15: 46311.613 | C15: 65.25 | D15: 1.0875 | E15: 14 | F15: 769537 | G15: 325 | H15: 0.3953 | I15: 1.588465 | J15: 7.06037 | K15: -0.34608 | L15: -0.03345 | M15: -0.4014 | O15: 11 | P15: 3.16 | R15: 11 | S15: 3.28
A16: DOPC 1 | B16: 46311.613 | C16: 70.234 | D16: 1.1705667 | E16: 15 | F16: 774537 | G16: 326.4 | H16: 0.5 | I16: 1.595308 | J16: 7.01999 | K16: -0.38646 | L16: -0.04038 | M16: -0.48611557 | O16: 12 | P16: 3.15 | R16: 12 | S16: 3.25
A17: DOPC 1 | B17: 46311.613 | C17: 75.234 | D17: 1.2539 | E17: 16 | F17: 779537 | G17: 327.84 | H17: 0.6124 | I17: 1.602346 | J17: 6.97846 | K17: -0.42799 | L17: -0.04153 | M17: -0.49836
A18: DOPC 1 | B18: 46311.613 | C18: 80.234 | D18: 1.3372333 | E18: 17 | F18: 784537 | G18: 328.92 | H18: 0.6187 | I18: 1.607625 | J18: 6.94732 | K18: -0.45913 | L18: -0.03114 | M18: -0.37368 | O18: DOPC source metadata
A19: DOPC 1 | B19: 46311.613 | C19: 85.234 | D19: 1.4205667 | E19: 18 | F19: 789537 | G19: 330.64 | H19: 0.5449 | I19: 1.616031 | J19: 6.89771 | K19: -0.50874 | L19: -0.04961 | M19: -0.59532
A20: DOPC 1 | B20: 46311.613 | C20: 90.219 | D20: 1.50365 | E20: 19 | F20: 794536 | G20: 331.44 | H20: 0.4921 | I20: 1.619941 | J20: 6.87464 | K20: -0.53181 | L20: -0.02307 | M20: -0.27767302 | O20: DOPC 1 | P20: 2026-10-16_10-41-34_DOPC_pH_change_1.xlsx
A21: DOPC 1 | B21: 46311.613 | C21: 95.219 | D21: 1.5869833 | E21: 20 | F21: 799537 | G21: 333.04 | H21: 0.5229 | I21: 1.627762 | J21: 6.8285 | K21: -0.57795 | L21: -0.04614 | M21: -0.55368 | O21: Experiment name | P21: DOPC_pH_change
A22: DOPC 1 | B22: 46311.613 | C22: 100.219 | D22: 1.6703167 | E22: 21 | F22: 804537 | G22: 334.44 | H22: 0.4921 | I22: 1.634604 | J22: 6.78812 | K22: -0.61833 | L22: -0.04038 | M22: -0.48456 | O22: Start time | P22: 46311.612
A23: DOPC 1 | B23: 46311.613 | C23: 105.203 | D23: 1.7533833 | E23: 22 | F23: 809537 | G23: 335.24 | H23: 0.433 | I23: 1.638514 | J23: 6.76505 | K23: -0.6414 | L23: -0.02307 | M23: -0.27772873 | O23: End time | P23: 46311.626
A24: DOPC 1 | B24: 46311.613 | C24: 110.219 | D24: 1.8369833 | E24: 23 | F24: 814537 | G24: 336.32 | H24: 0.4593 | I24: 1.643793 | J24: 6.7339 | K24: -0.67255 | L24: -0.03115 | M24: -0.37260766 | O24: Stop reason | P24: stopped by user
A25: DOPC 1 | B25: 46311.614 | C25: 115.203 | D25: 1.92005 | E25: 24 | F25: 819537 | G25: 337.52 | H25: 0.5078 | I25: 1.649658 | J25: 6.69929 | K25: -0.70716 | L25: -0.03461 | M25: -0.41665329 | O25: Operator notes | P25: Add sample conditions, treatment, concentration, temperature, and UV timing here.
A26: DOPC 1 | B26: 46311.614 | C26: 120.203 | D26: 2.0033833 | E26: 25 | F26: 824537 | G26: 338.36 | H26: 0.4921 | I26: 1.653763 | J26: 6.67507 | K26: -0.73138 | L26: -0.02422 | M26: -0.29064 | O26: Serial port | P26: COM3
A27: DOPC 1 | B27: 46311.614 | C27: 125.203 | D27: 2.0867167 | E27: 26 | F27: 829537 | G27: 339.8 | H27: 0.5 | I27: 1.660801 | J27: 6.63354 | K27: -0.77291 | L27: -0.04153 | M27: -0.49836 | O27: Sample interval (s) | P27: 5
A28: DOPC 1 | B28: 46311.614 | C28: 130.203 | D28: 2.17005 | E28: 27 | F28: 834537 | G28: 340.92 | H28: 0.3853 | I28: 1.666276 | J28: 6.60124 | K28: -0.80521 | L28: -0.0323 | M28: -0.3876 | O28: Requested duration (min) | P28: 60
A29: DOPC 1 | B29: 46311.614 | C29: 135.187 | D29: 2.2531167 | E29: 28 | F29: 839537 | G29: 341.84 | H29: 0.4593 | I29: 1.670772 | J29: 6.57471 | K29: -0.83174 | L29: -0.02653 | M29: -0.31938202 | O29: Number of readings | P29: 242
A30: DOPC 1 | B30: 46311.614 | C30: 140.203 | D30: 2.3367167 | E30: 29 | F30: 844537 | G30: 342.68 | H30: 0.4677 | I30: 1.674878 | J30: 6.55048 | K30: -0.85597 | L30: -0.02423 | M30: -0.28983254 | O30: Initial pH | P30: 7.40645
A31: DOPC 1 | B31: 46311.614 | C31: 145.187 | D31: 2.4197833 | E31: 30 | F31: 849537 | G31: 343.6 | H31: 0.4921 | I31: 1.679374 | J31: 6.52395 | K31: -0.8825 | L31: -0.02653 | M31: -0.31938202 | O31: Final pH | P31: 3.89028
A32: DOPC 1 | B32: 46311.614 | C32: 150.187 | D32: 2.5031167 | E32: 31 | F32: 854538 | G32: 344.6 | H32: 0.4841 | I32: 1.684262 | J32: 6.49511 | K32: -0.91134 | L32: -0.02884 | M32: -0.34608 | O32: Net pH change | P32: -3.51617
A33: DOPC 1 | B33: 46311.614 | C33: 155.187 | D33: 2.58645 | E33: 32 | F33: 859537 | G33: 345.2 | H33: 0.4841 | I33: 1.687194 | J33: 6.4778 | K33: -0.92865 | L33: -0.01731 | M33: -0.20772 | O33: Minimum pH | P33: 3.89028
A34: DOPC 1 | B34: 46311.614 | C34: 160.187 | D34: 2.6697833 | E34: 33 | F34: 864537 | G34: 346.6 | H34: 0.4841 | I34: 1.694037 | J34: 6.43743 | K34: -0.96902 | L34: -0.04037 | M34: -0.48444 | O34: Maximum pH | P34: 7.42491
A35: DOPC 1 | B35: 46311.614 | C35: 165.172 | D35: 2.7528667 | E35: 34 | F35: 869538 | G35: 347.4 | H35: 0.4921 | I35: 1.697947 | J35: 6.41436 | K35: -0.99209 | L35: -0.02307 | M35: -0.27767302 | O35: Mean pH | P35: 4.8972222
A36: DOPC 1 | B36: 46311.614 | C36: 170.187 | D36: 2.83645 | E36: 35 | F36: 874536 | G36: 348.08 | H36: 0.566 | I36: 1.701271 | J36: 6.39474 | K36: -1.01171 | L36: -0.01962 | M36: -0.23473579 | O36: pH standard deviation | P36: 1.0656703
A37: DOPC 1 | B37: 46311.614 | C37: 175.172 | D37: 2.9195333 | E37: 36 | F37: 879537 | G37: 349.28 | H37: 0.4507 | I37: 1.707136 | J37: 6.36014 | K37: -1.04631 | L37: -0.0346 | M37: -0.41644935 | O37: Linear pH rate (pH/min) | P37: -0.16848988
A38: DOPC 1 | B38: 46311.614 | C38: 180.172 | D38: 3.0028667 | E38: 37 | F38: 884537 | G38: 350.12 | H38: 0.4419 | I38: 1.711241 | J38: 6.33591 | K38: -1.07054 | L38: -0.02423 | M38: -0.29076 | O38: Calibration slope | P38: -0.02883994
... A41: DOPC 1 | B41: 46311.614 | C41: 195.156 | D41: 3.2526 | E41: 40 | F41: 899537 | G41: 352.88 | H41: 0.4239 | I41: 1.724731 | J41: 6.25631 | K41: -1.15014 | L41: -0.02654 | M41: -0.31950241 | O41: Calibration point count | P41: 3
A42: DOPC 1 | B42: 46311.615 | C42: 200.14 | D42: 3.3356667 | E42: 41 | F42: 904537 | G42: 353.44 | H42: 0.4921 | I42: 1.727468 | J42: 6.24016 | K42: -1.16629 | L42: -0.01615 | M42: -0.19442215
...
